I'm sorry, but an uncaught exception occurred.

While running game code:
  File "game/script.rpy", line 63, in script
    m "Why are you concerning me?"
Exception: Sayer 'm' is not defined.

-- Full Traceback ------------------------------------------------------------

Full traceback:
  File "game/script.rpy", line 63, in script
    m "Why are you concerning me?"
  File "C:\Users\aaron\Desktop\renpy-7.3.5-sdk\renpy\ast.py", line 678, in execute
    who = eval_who(self.who, self.who_fast)
  File "C:\Users\aaron\Desktop\renpy-7.3.5-sdk\renpy\ast.py", line 576, in eval_who
    raise Exception("Sayer '%s' is not defined." % who.encode("utf-8"))
Exception: Sayer 'm' is not defined.

Windows-8-6.2.9200
Ren'Py 7.3.5.606
HCIanxiety 1.0
Sat Nov 21 22:11:05 2020
